[2024-01-31T10:28:09.179+0000] {taskinstance.py:1956} INFO - Dependencies all met for dep_context=non-requeueable deps ti=<TaskInstance: data_ingestion_gcs_dag.yellow_tripdata_2022-03.parquet_to_gcs_task scheduled__2024-01-30T00:00:00+00:00 [queued]>
[2024-01-31T10:28:09.182+0000] {taskinstance.py:1956} INFO - Dependencies all met for dep_context=requeueable deps ti=<TaskInstance: data_ingestion_gcs_dag.yellow_tripdata_2022-03.parquet_to_gcs_task scheduled__2024-01-30T00:00:00+00:00 [queued]>
[2024-01-31T10:28:09.183+0000] {taskinstance.py:2170} INFO - Starting attempt 2 of 2
[2024-01-31T10:28:09.188+0000] {taskinstance.py:2191} INFO - Executing <Task(PythonOperator): yellow_tripdata_2022-03.parquet_to_gcs_task> on 2024-01-30 00:00:00+00:00
[2024-01-31T10:28:09.192+0000] {standard_task_runner.py:60} INFO - Started process 550 to run task
[2024-01-31T10:28:09.196+0000] {standard_task_runner.py:87} INFO - Running: ['***', 'tasks', 'run', 'data_ingestion_gcs_dag', 'yellow_tripdata_2022-03.parquet_to_gcs_task', 'scheduled__2024-01-30T00:00:00+00:00', '--job-id', '32', '--raw', '--subdir', 'DAGS_FOLDER/data_ingestion_gcs_dag.py', '--cfg-path', '/tmp/tmp0jk2xnlr']
[2024-01-31T10:28:09.197+0000] {standard_task_runner.py:88} INFO - Job 32: Subtask yellow_tripdata_2022-03.parquet_to_gcs_task
[2024-01-31T10:28:09.224+0000] {task_command.py:423} INFO - Running <TaskInstance: data_ingestion_gcs_dag.yellow_tripdata_2022-03.parquet_to_gcs_task scheduled__2024-01-30T00:00:00+00:00 [running]> on host 7c676a75bc22
[2024-01-31T10:28:09.263+0000] {taskinstance.py:2480} INFO - Exporting env vars: AIRFLOW_CTX_DAG_OWNER='***' AIRFLOW_CTX_DAG_ID='data_ingestion_gcs_dag' AIRFLOW_CTX_TASK_ID='yellow_tripdata_2022-03.parquet_to_gcs_task' AIRFLOW_CTX_EXECUTION_DATE='2024-01-30T00:00:00+00:00' AIRFLOW_CTX_TRY_NUMBER='2' AIRFLOW_CTX_DAG_RUN_ID='scheduled__2024-01-30T00:00:00+00:00'
[2024-01-31T10:28:09.267+0000] {_metadata.py:139} WARNING - Compute Engine Metadata server unavailable on attempt 1 of 3. Reason: [Errno 111] Connection refused
[2024-01-31T10:28:09.267+0000] {_metadata.py:139} WARNING - Compute Engine Metadata server unavailable on attempt 2 of 3. Reason: [Errno 111] Connection refused
[2024-01-31T10:28:09.267+0000] {_metadata.py:139} WARNING - Compute Engine Metadata server unavailable on attempt 3 of 3. Reason: [Errno 111] Connection refused
[2024-01-31T10:28:09.268+0000] {_default.py:338} WARNING - Authentication failed using Compute Engine authentication due to unavailable metadata server.
[2024-01-31T10:28:09.268+0000] {taskinstance.py:2698} ERROR - Task failed with exception
Traceback (most recent call last):
  File "/home/airflow/.local/lib/python3.8/site-packages/airflow/models/taskinstance.py", line 433, in _execute_task
    result = execute_callable(context=context, **execute_callable_kwargs)
  File "/home/airflow/.local/lib/python3.8/site-packages/airflow/operators/python.py", line 199, in execute
    return_value = self.execute_callable()
  File "/home/airflow/.local/lib/python3.8/site-packages/airflow/operators/python.py", line 216, in execute_callable
    return self.python_callable(*self.op_args, **self.op_kwargs)
  File "/opt/airflow/dags/data_ingestion_gcs_dag.py", line 58, in upload_to_gcs
    client = storage.Client()
  File "/home/airflow/.local/lib/python3.8/site-packages/google/cloud/storage/client.py", line 172, in __init__
    super(Client, self).__init__(
  File "/home/airflow/.local/lib/python3.8/site-packages/google/cloud/client/__init__.py", line 320, in __init__
    _ClientProjectMixin.__init__(self, project=project, credentials=credentials)
  File "/home/airflow/.local/lib/python3.8/site-packages/google/cloud/client/__init__.py", line 268, in __init__
    project = self._determine_default(project)
  File "/home/airflow/.local/lib/python3.8/site-packages/google/cloud/client/__init__.py", line 287, in _determine_default
    return _determine_default_project(project)
  File "/home/airflow/.local/lib/python3.8/site-packages/google/cloud/_helpers/__init__.py", line 152, in _determine_default_project
    _, project = google.auth.default()
  File "/home/airflow/.local/lib/python3.8/site-packages/google/auth/_default.py", line 691, in default
    raise exceptions.DefaultCredentialsError(_CLOUD_SDK_MISSING_CREDENTIALS)
google.auth.exceptions.DefaultCredentialsError: Your default credentials were not found. To set up Application Default Credentials, see https://cloud.google.com/docs/authentication/external/set-up-adc for more information.
[2024-01-31T10:28:09.274+0000] {taskinstance.py:1138} INFO - Marking task as FAILED. dag_id=data_ingestion_gcs_dag, task_id=yellow_tripdata_2022-03.parquet_to_gcs_task, execution_date=20240130T000000, start_date=20240131T102809, end_date=20240131T102809
[2024-01-31T10:28:09.280+0000] {standard_task_runner.py:107} ERROR - Failed to execute job 32 for task yellow_tripdata_2022-03.parquet_to_gcs_task (Your default credentials were not found. To set up Application Default Credentials, see https://cloud.google.com/docs/authentication/external/set-up-adc for more information.; 550)
[2024-01-31T10:28:09.289+0000] {local_task_job_runner.py:234} INFO - Task exited with return code 1
[2024-01-31T10:28:09.300+0000] {taskinstance.py:3280} INFO - 0 downstream tasks scheduled from follow-on schedule check
